<?xml version="1.0"?>

<!-- 1) cd into the directory containing bot.urdf -->
<!-- 2) roslaunch urdf_tutorial display.launch model:=bot.urdf -->

<robot name="bot">

  <!-- Define colors to be used later (for visualization ONLY). -->
  <material name="white">
    <color rgba="1 1 1 1"/>
  </material>
  <material name="blue">
    <color rgba="0 0 0.8 1"/>
  </material>

  <!-- Define the links of the robot. -->
  <link name="base_link" />
  <link name="link_1" />
  <link name="link_2">
    <visual>
      <origin xyz="0 0 0.1" rpy="0 0 0" />
      <geometry>
        <cylinder length="0.2" radius="0.05" />
      </geometry>
      <material name="white" />
    </visual>
  </link>
  <link name="link_3">
    <visual>
      <origin xyz="0 0 0.2" rpy="0 0 0" />
      <geometry>
        <cylinder length="0.4" radius="0.05" />
      </geometry>
      <material name="blue" />
    </visual>
  </link>
  <link name="link_4">
    <visual>
      <origin xyz="0 0 0.1" rpy="0 0 0" />
      <geometry>
        <cylinder length="0.2" radius="0.05" />
      </geometry>
      <material name="white" />
    </visual>
  </link>
  <link name="link_5">
    <visual>
      <origin xyz="0 0 0.1" rpy="0 0 0" />
      <geometry>
        <cylinder length="0.2" radius="0.05" />
      </geometry>
      <material name="blue" />
    </visual>
  </link>
  <link name="ee_link" />

  <!-- Define the joints of the robot. -->
  <joint name="base_to_link_1" type="prismatic">
    <axis xyz="1 0 0" />
    <limit effort="1000.0" lower="-0.5" upper="0.5" velocity="0.5" />
    <origin xyz="0 0 0" rpy="0 0 0" />
    <parent link="base_link" />
    <child link="link_1" />
  </joint>

  <joint name="link_1_to_link_2" type="revolute">
    <axis xyz="0 0 1" />
    <limit effort="1000.0" lower="-1.507" upper="1.507" velocity="0.5" />
    <origin xyz="0 0 0" rpy="0 0 0" />
    <parent link="link_1" />
    <child link="link_2" />
  </joint>

  <joint name="link_2_to_link_3" type="revolute">
    <axis xyz="1 0 0" />
    <limit effort="1000.0" lower="0" upper="1.507" velocity="0.5" />
    <origin xyz="0 0 0.2" rpy="0 0 0" />
    <parent link="link_2" />
    <child link="link_3" />
  </joint>

  <joint name="link_3_to_link_4" type="revolute">
    <axis xyz="1 0 0" />
    <limit effort="1000.0" lower="-1.507" upper="1.507" velocity="0.5" />
    <origin xyz="0 0 0.4" rpy="0 0 0" />
    <parent link="link_3" />
    <child link="link_4" />
  </joint>

  <joint name="link_4_to_link_5" type="revolute">
    <axis xyz="1 0 0" />
    <limit effort="1000.0" lower="-1.507" upper="1.507" velocity="0.5" />
    <origin xyz="0 0 0.2" rpy="0 0 0" />
    <parent link="link_4" />
    <child link="link_5" />
  </joint>

  <joint name="link_5_to_ee_link" type="revolute">
    <axis xyz="0 0 1" />
    <limit effort="1000.0" lower="-1.507" upper="1.507" velocity="0.5" />
    <origin xyz="0 0 0.2" rpy="0 0 0" />
    <parent link="link_5" />
    <child link="ee_link" />
  </joint>

</robot>
